<?xml version="1.0" encoding="utf-8"?>

<robot name="MIRA3">
    <link name="root_link"/>

<!-- ********************************** BASE / Inertial Frame ********************************* -->

    <link name="platform_link">
	<visual>
        <geometry>
            <mesh filename="SPSRobot/AssemblyMira_URDF.obj"/>
        </geometry>
    </visual>
    </link>
    <joint name="platform_joint" type="fixed">
        <parent link="root_link"/>
        <child link="platform_link"/>
        <origin xyz="-1.3 0 -1.3" rpy="0 0 0"/>
    </joint>

<!-- ***************************************** WHEELS ***************************************** -->

<link name="frontRightWheel">
	<visual>
        <geometry>
            <mesh filename="SPSRobot/Mirr_Wheels_URDF.obj"/>
        </geometry>
        </visual>
    </link>
    <joint name="front_right_wheel_joint" type="continuous">
        <parent link="platform_link"/>
        <child link="frontRightWheel"/>
        <axis xyz="0 1 0"/>
        <origin rpy="0 0 0" xyz="0.183 -0.137 0"/>
        <limit lower="1" upper="-1" effort="0.0" velocity="0.837"/>
    </joint>

<link name="frontLeftWheel">
	<visual>
        <geometry>
            <mesh filename="SPSRobot/Whhesl_URDF.obj"/>
        </geometry>
        </visual>
        </visual>
        <collision>
            <geometry>
                <cylinder radius="0.078" length="0.05"/>
            </geometry>
        </collision>
    </visual>
        <collision>
            <geometry>
                <cylinder radius="0.078" length="0.05"/>
            </geometry>
        </collision>
    </link>
    <joint name="front_left_wheel_joint" type="continuous">
        <parent link="platform_link"/>
        <child link="frontLeftWheel"/>
        <axis xyz="0 1 0"/>
        <origin rpy="0 0 0" xyz="0.183 0.137 0"/>
        <limit lower="0" upper="2" effort="0.0" velocity="0.837"/>
    </joint>

<link name="rearLeftWheel">
	<visual>
        <geometry>
            <mesh filename="SPSRobot/Mirr_Wheels_URDF.obj"/>
        </geometry>
        </visual>
        </visual>
        <collision>
            <geometry>
                <cylinder radius="0.078" length="0.05"/>
            </geometry>
        </collision>
    </visual>
        <collision>
            <geometry>
                <cylinder radius="0.078" length="0.05"/>
            </geometry>
        </collision>
    </link>
    <joint name="rear_left_wheel_joint" type="continuous">
        <parent link="platform_link"/>
        <child link="rearLeftWheel"/>
        <axis xyz="0 1 0"/>
        <origin rpy="0 0 0" xyz="-0.183 0.137 0"/>
        <limit lower="0" upper="1" effort="0.0" velocity="0.837"/>
    </joint>

<link name="rearRightWheel">
	<visual>
        <geometry>
            <mesh filename="SPSRobot/Whhesl_URDF.obj"/>
        </geometry>
        </visual>
        </visual>
        <collision>
            <geometry>
                <cylinder radius="0.078" length="0.05"/>
            </geometry>
        </collision>
    </visual>
        <collision>
            <geometry>
                <cylinder radius="0.078" length="0.05"/>
            </geometry>
        </collision>
    </link>
    <joint name="rear_right_wheel_joint" type="continuous">
        <parent link="platform_link"/>
        <child link="rearRightWheel"/>
        <axis xyz="0 1 0"/>
        <origin rpy="0 0 0" xyz="-0.183 -0.137 0"/>
        <limit lower="-6.28" upper="6.28" effort="0.0" velocity="0.837"/>
    </joint>

<!-- **************************************** MOUNTING ******************************************* -->

    <joint name="KinovaMounting" type="fixed">
        <parent link="platform_link"/>
        <child link="KinovaBase"/>
        <origin rpy="3.1416 1.24 3.1416" xyz="0.02102 0 -0.01727"/>
    </joint>

    <link name="KinovaBase">
	<visual>
        <geometry>
            <mesh filename="SPSRobot/Link1.obj"/>
        </geometry>
    </visual>
    </link>

<!-- ****************************************** ARM ******************************************* -->

    <joint name="KinovaJoint1" type="continuous">
        <parent link="KinovaBase"/>
        <child link="KinovaLink1"/>
        <axis xyz="0 0 1"/>
        <origin xyz="0.0 0.0 0.0" rpy="0.0 0.0 0.0"/>
        <limit lower="-6.28" upper="6.28" effort="0.0" velocity="0.628"/>
    </joint>

    <link name="KinovaLink1">
	<visual>
        <geometry>
            <mesh filename="SPSRobot/Link2.obj"/>
        </geometry>
    </visual>
    </link>

    <joint name="KinovaJoint2" type="continuous">
        <parent link="KinovaLink1"/>
        <child link="KinovaLink2"/>
        <axis xyz="1 0 0"/>
        <origin rpy="3.1416 0.0 0.0" xyz="0 0 -0.2755"/>
        <limit lower="0.75" upper="5.54" effort="0.0" velocity="0.628"/>
    </joint>

    <link name="KinovaLink2">
	<visual>
        <geometry>
            <mesh filename="SPSRobot/Link3.obj"/>
        </geometry>
    </visual>
    </link>

    <joint name="KinovaJoint3" type="continuous">
        <parent link="KinovaLink2"/>
        <child link="KinovaLink3"/>
        <axis xyz="1 0 0"/>
        <origin rpy="0.0 3.1416 0.0" xyz="0 0 -0.410"/>
        <limit lower="0.3" upper="5.98" effort="0.0" velocity="0.628"/>
    </joint>

    <link name="KinovaLink3">
	<visual>
        <geometry>
            <mesh filename="SPSRobot/Link4.obj"/>
        </geometry>
    </visual>
    </link>

    <joint name="KinovaJoint4" type="continuous">
        <parent link="KinovaLink3"/>
        <child link="KinovaLink4"/>
        <axis xyz="0 0 1"/>
        <origin rpy="0.0 0 3.1416" xyz="-0.0098 0 -0.2073"/>
        <limit lower="-6.28" upper="6.28" effort="0.0" velocity="0.837"/>
    </joint>

    <link name="KinovaLink4">
	<visual>
        <geometry>
            <mesh filename="SPSRobot/Link5.obj"/>
        </geometry>
    </visual>
    </link>

    <joint name="KinovaJoint5" type="continuous">
        <parent link="KinovaLink4"/>
        <child link="KinovaLink5"/>
        <axis xyz="1 0 0"/>
        <origin rpy="0.0 3.1416 3.1416" xyz="0.0 0.0 -0.1038"/>
        <limit lower="1.2" upper="5.09" effort="0.0" velocity="0.837"/>
    </joint>

    <link name="KinovaLink5">
	<visual>
        <geometry>
            <mesh filename="SPSRobot/Link6.obj"/>
        </geometry>
    </visual>
    </link>

    <joint name="KinovaJoint6" type="continuous">
        <parent link="KinovaLink5"/>
        <child link="KinovaLink6"/>
        <axis xyz="0 0 1"/>
        <origin xyz="0.0 0.0 -0.1038" rpy="0.0 0.0 0.0"/>
        <limit lower="-6.28" upper="6.28" effort="0.0" velocity="0.837"/>
    </joint>

    <link name="KinovaLink6">
	<visual>
        <geometry>
            <mesh filename="SPSRobot/missing.obj"/>
        </geometry>
    </visual>
    </link>

<!-- ****************************************** END-EFFECTOR ******************************************* -->

    <joint name="endEffectorJoint" type="fixed">
        <parent link="KinovaLink6"/>
        <child link="leafLink"/>
        <origin xzy="0.0 0.0 0.0" rpy="0.0 0.0 0.0"/>
    </joint>

    <link name="leafLink"></link>

</robot>
