<?xml version="1.0" ?>
<robot name="2dof">

<link name="base_link">
    <visual>
      <origin xyz="0 0 0" rpy="0 0 0"/>
      <geometry>
        <cylinder length="0.2" radius="0.1"/>
      </geometry>
      <material name="White">
       <color rgba="1.0 1.0 1.0 1.0"/>
      </material>
    </visual>
  </link>

  <joint name="joint1" type="continuous">
    <parent link="base_link"/>
    <child link="link1"/>
    <origin xyz="0 0 0" rpy="0 0 0" />
    <axis xyz="0 0 1" />
  </joint>

  <link name="link1">
    <visual>
      <origin xyz="0.5 0 0"/>
      <geometry>
        <box size="1 0.05 0.05"/>
      </geometry>
      <material name="Red">
       <color rgba="0.9 0.9 0.9 1.0"/>
      </material>
    </visual>
  </link>

  <joint name="joint2" type="continuous">
    <parent link="link1"/>
    <child link="link2"/>
    <origin xyz="1 0 0" rpy="1.57079632679 0 0" />
    <axis xyz="0 1 0" />
  </joint>

  <link name="link2">
    <visual>
      <origin xyz="0.25 0 0"/>
      <geometry>
        <box size="0.5 0.05 0.05"/>
      </geometry>
      <material name="Blue">
       <color rgba="0.8 0.8 0.8 1.0"/>
      </material>
    </visual>
  </link>

  <joint name="joint3" type="prismatic">
    <parent link="link2"/>
    <child link="link3"/>
    <origin xyz="0.5 0 0" rpy="0 0 0" />
    <axis xyz="0 0 1" />
    <limit effort="30" velocity="1.0" lower="-0.15" upper="0.15" />
  </joint>

  <link name="link3">
    <visual>
      <origin xyz="0 0 0" rpy="-1.57079632679 0 0"/>
      <geometry>
        <box size="0.05 0.3 0.05"/>
      </geometry>
      <material name="Red">
       <color rgba="0.9 0.9 0.9 1.0"/>
      </material>
    </visual>
  </link>
  
</robot>